Workbook

Sheet 오픈소스&직접수집
A1: title | B1: authors | C1: journal | D1: publisher | E1: year | F1: doi
A2: Trends of fear and anger on YouTube during the initial stage of the COVID-19 outbreak in South Korea | B2: Jae-Joon Lee; Jongwoo Kim; Soo?Kyoung Lee | C2: BMC Public Health | E2: 2024 | F2: 10.1186/s12889-024-19023-6
A3: 키워드 네트워크를 활용한 국내 집단상담 연구 동향 분석(2008∼2022) | B3: Kwon, Kyoung-In; Kim, Min-Hyang | C3: 상담학연구 | D3: 한국상담학회 | E3: 2024 | F3: 10.15703/kjc.25.1.202402.117
A4: Literature Review of Extended Reality Research in Consumer | B4: Modeling | C4: Literature Review of Extended Reality Research in Consumer | E4: 2024 | F4: 10.53728/2765-6500.1627
A5: A study on research trends for pregnancy in adolescence: Focusing on text network analysis and topic modeling | B5: Seungmi Park; Eunju Kwak; Hye Ok Park; Jung Eun Hong | C5: The Journal of Korean Academic Society of Nursing Education | E5: 2024 | F5: 10.5977/jkasne.2024.30.2.149
A6: ‘어린이’와 ‘키즈’를 주제어로 하는 유튜브(YouTube) 콘텐츠 분석: LDA 토픽모델링을 활용하여 | B6: Lee, Keunyoung; Jung, Boomin | C6: 열린유아교육연구 | D6: 한국열린유아교육학회 | E6: 2024 | F6: 10.20437/KOAECE29-1-08
A7: 대한가정학회지 연구 동향 및 공저자 네트워크 분석: 2010∼2022년 게재 논문을 중심으로 | B7: Mi Jeong Park; Jung Hyun Chae; Han Ju | C7: Human Ecology Research | D7: 대한가정학회 | E7: 2024 | F7: 10.6115/her.2024.002
A8: 토픽모델링을 활용한 문화도시 관련 연구 동향 분석 | B8: Kim, Min-Sun | C8: 문화산업연구 | D8: 한국문화산업학회 | E8: 2024 | F8: 10.35174/JKCI.2024.03.24.1.47
A9: 경영·무역 학술논문의 의미 네트워크 분석법 도입에 관한 연구 | B9: Hong, Eui; Jeon, Ho-Jin; Kim, Young-Min | C9: 경영컨설팅연구 | D9: 한국경영컨설팅학회 | E9: 2024
A10: 국내 크리스천 코칭 연구동향 분석:키워드 네트워크 및 토픽모델링 분석을 중심으로 | B10: Choi, Yun-jeong; Kim, Yong-ku | C10: 코칭연구 | D10: 한국코칭학회 | E10: 2024
A11: 중고령 장애인 관련 국내 연구동향: 언어 네트워크 분석과 토픽모델링 활용 | B11: Yi Eunsil; Cho, Hye Chung | C11: 장애와 고용 | D11: 한국장애인고용공단 고용개발원 | E11: 2024 | F11: 10.15707/disem.2024.34.2.011
A12: 텍스트 마이닝을 활용한 노동시장 성과의 연구동향 분석 | B12: Donghwa Kim; Jiyoon Ban | C12: 직업능력개발연구 | D12: 한국직업능력연구원 | E12: 2024 | F12: 10.36907/krivet.2024.27.2.169
A13: 한국어 화용 교육 연구의 현황 및 과제- 토픽 모델링과 키워드 네트워크 분석을 중심으로 - | B13: Jungran Lee | C13: 영주어문 | D13: 영주어문학회 | E13: 2024
A14: Analyzing Demand for Customized Obesity Prevention and Management Across Adult Age Groups Using Focus Group Interview | B14: Jinah Park; Shinaeh Park; Mi So Kim | C14: INQUIRY The Journal of Health Care Organization Provision and Financing | E14: 2024 | F14: 10.1177/00469580241271152
A15: LDA topic modeling analysis of YouTube content with the keywords child” &amp; kids” | B15: Keunyoung Lee; Boomin Jung | C15: Korea open association for early childhood education | E15: 2024 | F15: 10.20437/koaece29-1-08
A16: Analysis of school sports policy research trends using text mining | B16: Min-Jun Kuk; Dae?Won Park | C16: Korean Journal of Teacher Education | E16: 2024 | F16: 10.14333/kjte.2024.40.2.04
A17: Analysis of Research Trends on Healthy Families Using LDA Topic Modeling : Focusing on the Periods of the 1st to 4th Basic Plans for Healthy Families | B17: 한국방송통신대학교 생활과학부 부교수; Hyunah Lee; Soombum Kwon | C17: Journal of Korean Family Resource Management Association | E17: 2024 | F17: 10.22626/jkfrma.2024.28.4.007
A18: Analysis of papers published in The Journal of Korean Academic Society of Nursing Education over 30 Years | B18: Seungmi Park; SuJeong Yu; Kyung-Choon Lim; Subin Choi; Eunyoung E. Suh | C18: The Journal of Korean Academic Society of Nursing Education | E18: 2024 | F18: 10.5977/jkasne.2024.30.4.382
A19: Exploring research trends in nursing organizational culture using topic modeling | B19: Eun?Jun Park; Chan Sook Park | C19: The Journal of Korean Academic Society of Nursing Education | E19: 2024 | F19: 10.5977/jkasne.2024.30.4.371
A20: Leveraging Digital Forensics in the Age of Smart Grids: A Survey of Tools and Techniques for Securing Electrical Power Systems | B20: Daniel Madan Raja S | C20: Journal of Electrical Systems | E20: 2024 | F20: 10.52783/jes.2024
A21: LDA 토픽모델링을 활용한 국내 영유아 돌봄 관련 연구 동향 분석 | B21: Chung, Chunghee; Lee, Hyorim; Jung, Boomin | C21: 열린유아교육연구 | D21: 한국열린유아교육학회 | E21: 2024 | F21: 10.20437/KOAECE29-5-02
A22: 공공무용단의 유튜브(YouTube)콘텐츠 표현유형에 대한 이용자 반응 분석 | B22: Taeyeon Kim | C22: 한국무용학회지 | D22: 한국무용학회 | E22: 2024 | F22: 10.26743/kaod.2024.24.1.011
A23: 네트워크 분석과 토픽모델링을 활용한 대학의 핵심역량 탐색 | B23: Mi-Hyun Bang; Youngmin Lee | C23: 한국콘텐츠학회 논문지 | D23: 한국콘텐츠학회 | E23: 2024 | F23: 10.5392/JKCA.2024.24.10.125
A24: 중독 관련 뉴스의 텍스트 네트워크 분석 및 시사점: 1990년부터 현재까지 | B24: Kim, Mee Sook | C24: 한국웰니스학회지 | D24: 한국웰니스학회 | E24: 2024 | F24: 10.21097/ksw.2024.11.19.4.207
A25: 청소년 임신에 대한 연구 동향 분석: 텍스트 네트워크 분석과 토픽 모델링 | B25: Park Seung Mi; EUNJU KWAK; HYE OK PARK; Hong, Jung Eun | C25: 한국간호교육학회지 | D25: 한국간호교육학회 | E25: 2024 | F25: 10.5977/jkasne.2024.30.2.149
A26: 키워드 네트워크 분석을 통한 유아·아동 비만 및 신체활동 관련 국내 연구 동향 분석 | B26: Na-Young An; Eun-Jung Kim | C26: 한국발육발달학회지 | D26: 한국발육발달학회 | E26: 2024 | F26: 10.34284/KJGD.2024.08.32.3.139
A27: 키워드 네트워크 분석을 활용한 국내 미술치료 질적 연구 동향 분석(2013～2024) | B27: Choi, Han-Na; Lim, Na-Young | C27: 예술심리치료연구 | D27: 한국예술심리치료학회 | E27: 2024 | F27: 10.32451/KJOAPS.2024.20.3.123
A28: 텍스트 마이닝을 활용한 학교체육정책 연구 동향 분석 | B28: Kuk, Min-Jun; Park, Dae-Won | C28: 교원교육 | D28: 교육연구원 | E28: 2024 | F28: 10.14333/KJTE.2024.40.2.04
A29: ‘계절의 변화 원인’단원 지도에 대한 초등예비교사들의 인식분석 | B29: lee yong seob | C29: 대한지구과학교육학회지 | D29: 대한지구과학교육학회 | E29: 2024
A30: 2023 카타르 아시안컵 축구협회를 둘러싼 여론 변화 탐색: 토픽모델링 분석을 중심으로 | B30: Kim, Nam-Gyu | C30: 한국융합과학회지 | D30: 한국융합과학회 | E30: 2024 | F30: 10.24826/KSCS.13.6.4
A31: A Comparative Analysis of Synonymous Verbs Based on American and British English Usage | B31: Ha, Myoung-Ho | C31: 언어학 연구 | D31: 한국중원언어학회 | E31: 2024 | F31: 10.17002/sil..72.202407.155
A32: A Study on Perception Survey of Preservice Elementary Teachers on Teaching Methods in Astronomy ? A Secondary Publication | B32: Yong-seob Lee | C32: International Education Forum | E32: 2024 | F32: 10.26689/ief.v2i1.6509
A33: A Study on the Degree Centrality Analysis of Meaningful Activities of Daily Living (ADL) in Male Stroke Patients : Focusing on Social Network Analysis | B33: 극동대학교 작업치료학과; Hyup Kim; Jin-Seok Oh | C33: 건강과 작업과학 | E33: 2024 | F33: 10.59910/kjhos.2024.5.1
A34: An Analysis of Counseling Research Trends Using Text Mining in South Korea | B34: THE KOREAN SOCIETY OF EDUCATIONAL THERAPY; Hye-Yon Seon; Hui-Ju Kim; Ye-Jee Kim; Ye-Rin Park | C34: Jounral of Educational Therapist | E34: 2024 | F34: 10.35185/kjet.16.3.3
A35: An Analysis of Research Trends Related to Children's Play Therapy Using Keyword Network Analysis | B35: Jing An; Seo-jin Baek | C35: Korean Association For Learner-Centered Curriculum And Instruction | E35: 2024 | F35: 10.22251/jlcci.2024.24.24.73
A36: Analysis of Domestic Dental Hygienist Research Trends | B36: Kyung Hui Moon | C36: International Journal of Clinical Preventive Dentistry | D36: 대한예방치과학회 | E36: 2024 | F36: 10.15236/ijcpd.2024.20.3.110
A37: Analysis of football research trends using text network analysis | B37: Jongwon Kim | C37: PLoS ONE | E37: 2024 | F37: 10.1371/journal.pone.0299782
A38: Analysis of Research Trends in Christian Coaching in South Korea - Keyword Network and Topic Modeling Analysis | B38: Yunjeong Choi; Yong-gu Kim | C38: Journal of Korean Coaching Research | E38: 2024 | F38: 10.20325/kca.2024.17.2.97
A39: Analysis of research trends on Childcare” for young children in Korea using LDA topic modeling | B39: Chunghee Chung; Hyorim Lee; Boomin Jung | C39: Korea open association for early childhood education | E39: 2024 | F39: 10.20437/koaece29-5-02
A40: Analysis of Research Trends on Cultural City Using Topic Modeling | B40: Minsun Kim | C40: Journal of Korea Culture Industry | E40: 2024 | F40: 10.35174/jkci.2024.03.24.1.47
...

Sheet wos(corecollection)_260528
A1: Publication Type | B1: Authors | C1: Book Authors | D1: Book Editors | E1: Book Group Authors | F1: Author Full Names | G1: Book Author Full Names | H1: Group Authors | I1: Article Title | J1: Source Title | K1: Book Series Title | L1: Book Series Subtitle | M1: Language | N1: Document Type | O1: Conference Title | P1: Conference Date | Q1: Conference Location | R1: Conference Sponsor | S1: Conference Host | T1: Author Keywords | U1: Keywords Plus | V1: Abstract | W1: Addresses | X1: Affiliations | Y1: Reprint Addresses | Z1: Email Addresses | AA1: Researcher Ids | AB1: ORCIDs | AC1: Funding Orgs | AD1: Funding Name Preferred | AE1: Funding Text | AF1: Cited References | AG1: Cited Reference Count | AH1: Times Cited, WoS Core | AI1: Times Cited, All Databases | AJ1: 180 Day Usage Count | AK1: Since 2013 Usage Count | AL1: Publisher | AM1: Publisher City | AN1: Publisher Address | AO1: ISSN | AP1: eISSN | AQ1: ISBN | AR1: Journal Abbreviation | AS1: Journal ISO Abbreviation | AT1: Publication Date | AU1: Publication Year | AV1: Volume | AW1: Issue | AX1: Part Number | AY1: Supplement | AZ1: Special Issue | BA1: Meeting Abstract | BB1: Start Page | BC1: End Page | BD1: Article Number | BE1: DOI | BF1: DOI Link | BG1: Book DOI | BH1: Early Access Date | BI1: Number of Pages | BJ1: WoS Categories | BK1: Web of Science Index | BL1: Research Areas | BM1: IDS Number | BN1: Pubmed Id | BO1: Open Access Designations | BP1: Highly Cited Status | BQ1: Hot Paper Status | BR1: Date of Export | BS1: UT (Unique WOS ID) | BT1: Web of Science Record | BU1: doi 중복 | BV1: 제목 중복
A2: netminer 검색 | B2: Kang, N; Ahn, S; Jeong, HW | F2: Kang, Naru; Ahn, Shinhye; Jeong, Hye Won | I2: A Text Network Analysis of Nurse Managers' Feedback Journals | J2: CIN-COMPUTERS INFORMATICS NURSING | N2: Article | V2: This study employed text network analysis to examine nurse managers' feedback journals for new nurses, highlighting the critical need for structured support during their transition period. A total of 429 feedback journals were documented by 32 nurse managers for 239 new nurses between September 2019 and March 2021 in South Korea, aiming to identify the challenges faced by new nurses and explore keyword relationships and thematic patterns. The analysis process included 4 stages: data preprocessing, keyword extraction, network and centrality analysis, and subtheme analysis. Using NetMiner 4.5.0, the analysis identified several central keywords in the feedback journals, with performance showing the highest centrality values (degree centrality = 0.448, closeness centrality = 0.580, betweenness centrality = 0.117), followed by experience and explanation. Through community detection analysis using the eigenvector method, 3 distinct subthemes emerged from the network structure: clinical practice fundamentals, learning and development process, and support and educational system. The findings of this study provide empirical evidence for developing structured feedback programs and enhancing nurse managers' interviewing competencies. The findings provide empirical evidence regarding linguistic patterns and thematic structures in nurse managers' feedback, suggesting systematic documentation protocols and utilization of these insights to inform structured feedback initiatives, thereby supporting new nurses' development. | W2: [Ahn, Shinhye] Chonnam Natl Univ Hosp, Dept Nursing, Gwangju, South Korea; [Jeong, Hye Won] Sunchon Natl Univ, Dept Nursing, Sunchon Si, Jeollanam Do, South Korea; [Jeong, Hye Won] Korea Natl Univ Transportat, Dept Nursing, 61 Daehak Ro, Jeungpyeong 27909, Chungcheongbuk, South Korea | Y2: Jeong, HW (corresponding author), Korea Natl Univ Transportat, Dept Nursing, 61 Daehak Ro, Jeungpyeong 27909, Chungcheongbuk, South Korea. | Z2: knr5318@naver.com; chunyanggirl@naver.com; hyewon1129@ut.ac.kr | AG2: 40 | AH2: 0 | AI2: 0 | AT2: MAR | AU2: 2026 | AV2: 44 | AW2: 3 | BD2: e01373 | BE2: 10.1097/CIN.0000000000001373 | BF2: =HYPERLINK("http://dx.doi.org/10.1097/CIN.0000000000001373","http://dx.doi.org/10.1097/CIN.0000000000001373") -> http://dx.doi.org/10.1097/CIN.0000000000001373 | BR2: 2026-05-29 | BS2: WOS:001708080600007 | BT2: =HYPERLINK("https%3A%2F%2Fwww.webofscience.com%2Fwos%2Fwoscc%2Ffull-record%2FWOS:001708080600007","View Full Record in Web of Science") -> View Full Record in Web of Science | BU2: =COUNTIF('오픈소스&직접수집'!F:F,'wos(corecollection)_260528'!BE2) -> 0 | BV2: =COUNTIF('오픈소스&직접수집'!A:A,'wos(corecollection)_260528'!I2) -> 1 | BW2: =SUM(BU2:BV2) -> 1
A3: netminer 검색 | B3: Kang, N; Zhang, P; Li, H; Wen, SS; Ji, CY; Yang, YQ | F3: Kang, Ning; Zhang, Peng; Li, Hao; Wen, Sisi; Ji, Chaoyang; Yang, Yongqiang | I3: Network Specification Mining With High Fidelity, Scalability, and Readability | J3: IEEE TRANSACTIONS ON NETWORKING | N3: Article | V3: Network specification, which describes what an existing network is designed for, can help operators better understand and manage their networks, and is a critical pre-condition for network verification and synthesis tools to work. Existing tools for specification mining either cannot scale to large networks, or scale by sacrificing fidelity. Moreover, the specification contains a huge number of low-level intents (e.g., tens of thousands of pairwise reachability), making it hard for operators to read. To this end, this paper presents NetMiner, which can mine specification from network configurations, with high scalability, fidelity, and easier to read. The key idea of NetMiner is to faithfully simulate the network routing and forwarding behaviors with control plane simulators and data plane verifiers, so as to achieve high fidelity. Meanwhile, NetMiner improves the scalability by identifying relevant failure scenarios, and aggregating them to significantly reduce the number of needed simulations. Moreover, NetMiner clusters similar low-level intents into a high-level intent, to make the specification more concise and easier to read. Experiments using real configurations from a large cloud service provider and synthetic configurations show that NetMiner can mine specification 10 x faster, and reduce the number of intents by 100 x, compared to state-of-the-art tools. | W3: [Kang, Ning; Zhang, Peng; Li, Hao; Wen, Sisi] Xi An Jiao Tong Univ, Minist Educ, MOE Key Lab Intelligent Networks & Network Secur, Xian 710049, Peoples R China; [Ji, Chaoyang; Yang, Yongqiang] Huawei Cloud Comp Technol Co Ltd, Beijing 100015, Peoples R China | Y3: Zhang, P (corresponding author), Xi An Jiao Tong Univ, Minist Educ, MOE Key Lab Intelligent Networks & Network Secur, Xian 710049, Peoples R China. | Z3: kangning2018@foxmail.com; p-zhang@xjtu.edu.cn; hao.li@xjtu.edu.cn; sswen0427@gmail.com; jichaoyang@huawei.com; yangyongqiang@huawei.com | AG3: 50 | AH3: 0 | AI3: 0 | AU3: 2026 | AV3: 34 | BB3: 737 | BC3: 752 | BE3: 10.1109/TON.2025.3607440 | BF3: =HYPERLINK("http://dx.doi.org/10.1109/TON.2025.3607440","http://dx.doi.org/10.1109/TON.2025.3607440") -> http://dx.doi.org/10.1109/TON.2025.3607440 | BH3: SEP 2025 | BR3: 2026-05-29 | BS3: WOS:001582265700001 | BT3: =HYPERLINK("https%3A%2F%2Fwww.webofscience.com%2Fwos%2Fwoscc%2Ffull-record%2FWOS:001582265700001","View Full Record in Web of Science") -> View Full Record in Web of Science | BU3: =COUNTIF('오픈소스&직접수집'!F:F,'wos(corecollection)_260528'!BE3) -> 0 | BV3: =COUNTIF('오픈소스&직접수집'!A:A,'wos(corecollection)_260528'!I3) -> 0 | BW3: =SUM(BU3:BV3) -> 0
A4: netminer 검색 | B4: Oh, J; Son, S; Park, JH | F4: Oh, Jinseok; Son, Sungmin; Park, Jin-Hyuck | I4: An analysis of adolescent leisure activity structure based on subjective well-being: Focusing on social network analysis | J4: PLOS ONE | N4: Article | V4: This study examines how adolescent leisure activity networks relate to subjective well-being (SWB) using Statistics Korea's 2019 Time Use Survey. The analysis includes 241 high-SWB and 241 low-SWB adolescents, assessing network density, inclusiveness, average distance, isolated nodes, degree centrality, and cohesion through NetMiner 4.0, with descriptive statistics processed in SPSS ver. 25.0. The results show clear differences in leisure activity networks. High-SWB adolescents engaged in more social activities and sports, while low-SWB adolescents participated in fewer, more solitary activities. High-SWB networks were diverse and well-connected, whereas low-SWB networks were more fragmented. Screen-based activities also played different roles: supporting social connections in high-SWB adolescents but reinforcing isolation in low-SWB adolescents. This study visually highlights that leisure participation varies by SWB level. The findings suggest that promoting diverse and interactive leisure activities can improve adolescent well-being, offering insights for policy and intervention programs. | W4: [Oh, Jinseok; Park, Jin-Hyuck] Univ Soonchunhyang, Soonchunhyang Except Children Inst, Asan, Chungcheongnam, South Korea; [Son, Sungmin] Yonsei Univ, Wonju Coll Med, Dept Psychiat, Wonju Si, Kangwon Do, South Korea | Y4: Park, JH (corresponding author), Univ Soonchunhyang, Soonchunhyang Except Children Inst, Asan, Chungcheongnam, South Korea. | Z4: roophy@naver.com | AG4: 34 | AH4: 0 | AI4: 0 | AU4: 2025 | AV4: 20 | AW4: 5 | BD4: e0322956 | BE4: 10.1371/journal.pone.0322956 | BF4: =HYPERLINK("http://dx.doi.org/10.1371/journal.pone.0322956","http://dx.doi.org/10.1371/journal.pone.0322956") -> http://dx.doi.org/10.1371/journal.pone.0322956 | BR4: 2026-05-29 | BS4: WOS:001488720800043 | BT4: =HYPERLINK("https%3A%2F%2Fwww.webofscience.com%2Fwos%2Fwoscc%2Ffull-record%2FWOS:001488720800043","View Full Record in Web of Science") -> View Full Record in Web of Science | BU4: =COUNTIF('오픈소스&직접수집'!F:F,'wos(corecollection)_260528'!BE4) -> 0 | BV4: =COUNTIF('오픈소스&직접수집'!A:A,'wos(corecollection)_260528'!I4) -> 0 | BW4: =SUM(BU4:BV4) -> 0
A5: netminer 검색 | B5: Seon, SH; Jeong, HW; Choi, JY | F5: Seon, Sun Hee; Jeong, Hye Won; Choi, Ja Yun | I5: Exploring the Knowledge Structure of Research for Nurse Preceptor Training Programs Using Text Network Analysis and Topic Modeling | J5: CIN-COMPUTERS INFORMATICS NURSING | N5: Article | V5: PurposeThis study utilized text network analysis and topic modeling to examine the research landscape of nurse preceptor training programs and facilitate the adaptation of new nurses in Korea and internationally.MethodsAbstracts from three Korean and 45 international studies on preceptor nurse training programs were collected. Keywords and meaningful morphemes from the abstracts and main text were analyzed and refined. A co-occurrence matrix of keywords was generated to analyze degree, closeness, and betweenness centrality using NetMiner 4.5.0 software. Topic modeling was used to identify key thematic structures.ResultsAmong the top 10 ranked keywords, five common terms-clinical competence, educator, nursing practice, teaching strategy, and mentoring-emerged across both frequency and centrality measures. Topic modeling identified four major subtopics: nurse preceptor programs for strengthening partnership skills and professional insights, communication programs to enhance the self-care competence of nurse preceptors, simulation programs to strengthen the expertise of nurse preceptors, and nurse preceptor programs to foster emotional empathy and growth.ConclusionThis study improves patient safety and professional competence by promoting optimal clinical decision-making for new nurse preceptees. Future research should develop educational programs that foster mutual empathy and professional growth between nurse preceptors and new nurse preceptees. | W5: [Seon, Sun Hee] Chonnam Natl Univ Hosp, Gwangju, South Korea; [Jeong, Hye Won] Korea Natl Univ Transportat, Jeungpyeong Gun, Chungcheongbuk, South Korea; [Choi, Ja Yun] Chonnam Natl Univ, Gwangju, South Korea | Y5: Choi, JY (corresponding author), Chonnam Natl Univ, Coll Nursing, 160 Baekseo ro, Gwangju 61469, South Korea. | Z5: Seon00509@hanmail.net; hyewon1129@ut.ac.kr; choijy@jnu.ac.kr | AG5: 33 | AH5: 0 | AI5: 0 | AT5: SEP | AU5: 2025 | AV5: 43 | AW5: 9 | BD5: e01347 | BE5: 10.1097/CIN.0000000000001347 | BF5: =HYPERLINK("http://dx.doi.org/10.1097/CIN.0000000000001347","http://dx.doi.org/10.1097/CIN.0000000000001347") -> http://dx.doi.org/10.1097/CIN.0000000000001347 | BR5: 2026-05-29 | BS5: WOS:001569257100006 | BT5: =HYPERLINK("https%3A%2F%2Fwww.webofscience.com%2Fwos%2Fwoscc%2Ffull-record%2FWOS:001569257100006","View Full Record in Web of Science") -> View Full Record in Web of Science | BU5: =COUNTIF('오픈소스&직접수집'!F:F,'wos(corecollection)_260528'!BE5) -> 0 | BV5: =COUNTIF('오픈소스&직접수집'!A:A,'wos(corecollection)_260528'!I5) -> 0 | BW5: =SUM(BU5:BV5) -> 0
A6: netminer 검색 | B6: Ahn, S; Jeong, HW | F6: Ahn, Shinhye; Jeong, Hye Won | I6: Analysis of clinical nurse educators' mentoring feedback on new nurse journals at a tertiary hospital in South Korea: utilizing text network analysis | J6: BMC NURSING | N6: Article | V6: BackgroundThe gap between knowledge and clinical practice causes stress and reality shock, contributing to low job satisfaction and high turnover among new nurses; in 2023, the turnover rate in South Korea reached 52.4%. Korean preceptorship programs are often too brief to adequately support new nurses' adaptation. Clinical nurse educators (CNEs) play a crucial role in addressing these issues by offering knowledge transfer, emotional support, and career guidance. Therefore, strategies to strengthen CNEs' coaching and mentoring skills are essential to support new nurses' stable clinical adaptation. This study analyzed how CNEs mentored new hospital nurses by responding to their post-entry journals.MethodsThis study employed a quantitative content analysis. We used NetMiner 4.5.1 to conduct a text network analysis of 1,742 mentoring journal responses written by four CNEs for 120 new nurses at C University Hospital in South Korea between June 2021 and May 2022.ResultsThe keyword attitude had the highest frequency (726), emphasizing the clinical importance of fostering positive attitudes among new nurses. The keyword network had average centrality measures of degree (.15), closeness (.43), and betweenness (.05). Keywords with high centrality, such as attitude, importance, performance, and difficulty, highlighted mentoring practices focused on enhancing clinical judgment, nursing performance, and managing workplace challenges. Eigenvector analysis identified three subtopic groups with optimal modularity (.295). Subthemes included: 1) helping new nurses to improve their professional competence, 2) encouraging new nurses struggling to adapt to the field, and 3) empathy for new nurses' burdens and stress.ConclusionsThe findings revealed that the CNEs' mentoring feedback focused on encouraging new nurses to maintain a positive attitude, inspiring their personal and professional growth, and offering empathy and encouragement to help them cope with burdens and stress. Based on these findings, targeted training modules for CNEs and mentoring guidelines should be developed to further support new nurses' adaptation to clinical practice. | W6: [Ahn, Shinhye] Sunchon Natl Univ, Dept Nursing, Suncheon Si, Jeollanam Do, South Korea; [Jeong, Hye Won] Korea Natl Univ Transportat, Dept Nursing, 61 Daehak Ro, Jeungpyeong 27909, Chungcheongbuk, South Korea | Y6: Jeong, HW (corresponding author), Korea Natl Univ Transportat, Dept Nursing, 61 Daehak Ro, Jeungpyeong 27909, Chungcheongbuk, South Korea. | Z6: hyewon1129@ut.ac.kr | AG6: 36 | AH6: 0 | AI6: 0 | AT6: AUG 5 | AU6: 2025 | AV6: 24 | AW6: 1 | BD6: 1016 | BE6: 10.1186/s12912-025-03625-5 | BF6: =HYPERLINK("http://dx.doi.org/10.1186/s12912-025-03625-5","http://dx.doi.org/10.1186/s12912-025-03625-5") -> http://dx.doi.org/10.1186/s12912-025-03625-5 | BR6: 2026-05-29 | BS6: WOS:001545465400002 | BT6: =HYPERLINK("https%3A%2F%2Fwww.webofscience.com%2Fwos%2Fwoscc%2Ffull-record%2FWOS:001545465400002","View Full Record in Web of Science") -> View Full Record in Web of Science | BU6: =COUNTIF('오픈소스&직접수집'!F:F,'wos(corecollection)_260528'!BE6) -> 0 | BV6: =COUNTIF('오픈소스&직접수집'!A:A,'wos(corecollection)_260528'!I6) -> 1 | BW6: =SUM(BU6:BV6) -> 1
A7: netminer 검색 | B7: Oh, JS; Ho, JG; Park, JH | F7: Oh, Jin Seok; Ho, Jong Gab; Park, Jin-Hyuck | I7: The Impact of Late Adolescents' Social Network Strength on Mental Health | J7: BRAIN AND BEHAVIOR | N7: Article | V7: Purpose This study examined how social network strength (i.e., the intensity and frequency of interactions within one's personal network, assessed using centrality measures such as degree, closeness, betweenness, and eigenvector centrality) affects mental health. Methods The study was conducted with 108 first-year university students. Data were collected using a structured questionnaire, and NetMiner 4.0 was employed to analyze degree centrality, closeness centrality, betweenness centrality, and eigenvector centrality as indicators of social network centrality. Additionally, Quadratic Assignment Procedure (QAP) correlation analysis and QAP regression analysis were conducted to assess the relationship between social network strength and mental health. Results The study found that stronger social networks were linked to better mental health in late adolescence. Specifically, higher social network centrality was associated with lower levels of hopelessness and depression. QAP correlation analysis revealed that hopelessness had a significant negative correlation with in-closeness centrality (which reflects how easily one can be reached by others within the network) (r = -0.252, p < 0.05), while depression was negatively correlated with in-degree centrality (the number of direct incoming connections from peers) (r = -0.233, p < 0.05), in-closeness centrality (r = -0.256, p < 0.05), and eigenvector centrality (a measure of how well a person is connected to popular or influential members of the network) (r = -0.291, p < 0.01). QAP regression analysis further confirmed that weaker social ties, indicated by higher out-closeness centrality (how easily one can reach others, especially those at a distance), were associated with higher depressive symptoms (adj. R-2 = 0.143, F = 2.423, p < 0.05). These results suggest that building stronger and more integrated social networks may help reduce psychological distress and support mental well-being in late adolescence. Conclusion Stronger social networks in late adolescence are associated with better mental health, highlighting the importance of social connections. While correlational findings suggest general links between centrality and emotional well-being, the regression results underscore specific predictors with practical implications. In-degree, in-closeness, and eigenvector centrality were associated with reduced depressive symptoms, indicating that being well-integrated within a social network may offer protective benefits. In contrast, high out-closeness centrality predicted increased depression, suggesting that the effort required to maintain outward-reaching connections may impose psychological burdens. These findings suggest that targeted interventions should focus on strengthening inward social integration while addressing the stress related to maintaining extensive outward connections, providing direction for more effective youth mental health strategies. | W7: [Oh, Jin Seok; Ho, Jong Gab; Park, Jin-Hyuck] Soonchunhyang Univ, Soonchunhyang Except Children Inst, Asan, South Korea; [Park, Jin-Hyuck] Soonchunhyang Univ, Coll Med Sci, Dept Occupat Therapy, Asan, South Korea | Y7: Park, JH (corresponding author), Soonchunhyang Univ, Soonchunhyang Except Children Inst, Asan, South Korea.;Park, JH (corresponding author), Soonchunhyang Univ, Coll Med Sci, Dept Occupat Therapy, Asan, South Korea. | Z7: roophy@naver.com | AG7: 60 | AH7: 0 | AI7: 0 | AT7: SEP 27 | AU7: 2025 | AV7: 15 | AW7: 10 | BD7: e70910 | BE7: 10.1002/brb3.70910 | BF7: =HYPERLINK("http://dx.doi.org/10.1002/brb3.70910","http://dx.doi.org/10.1002/brb3.70910") -> http://dx.doi.org/10.1002/brb3.70910 | BR7: 2026-05-29 | BS7: WOS:001582615700001 | BT7: =HYPERLINK("https%3A%2F%2Fwww.webofscience.com%2Fwos%2Fwoscc%2Ffull-record%2FWOS:001582615700001","View Full Record in Web of Science") -> View Full Record in Web of Science | BU7: =COUNTIF('오픈소스&직접수집'!F:F,'wos(corecollection)_260528'!BE7) -> 0 | BV7: =COUNTIF('오픈소스&직접수집'!A:A,'wos(corecollection)_260528'!I7) -> 0 | BW7: =SUM(BU7:BV7) -> 0
A8: netminer 검색 | B8: Ahn, SH; Jeong, HW; Yang, SG; Jung, US; Choi, ML; Kim, HS | F8: Ahn, Shin Hye; Jeong, Hye Won; Yang, Seong Gyeong; Jung, Ue Seok; Choi, Myoung Lee; Kim, Heui Seon | I8: Temporal Exploration of New Nurses' Field Adaptation Using Text Network Analysis | J8: JOURNAL OF KOREAN ACADEMY OF NURSING | N8: Article | V8: Purpose: This study aimed to analyze the experiences of new nurses during their first year of hospital employment to gather data for the development of an evidence-based new nurse residency program focused on adaptability. Methods: This study was conducted at a tertiary hospital in Korea between March and August 2021 with 80 new nurses who wrote in critical reflective journals during their first year of work. NetMiner 4.5.0 was used to conduct a text network analysis of the critical reflective journals to uncover core keywords and topics across three periods. Results: In the journals, over time, degree centrality emerged as study and patient understanding for 1 to 3 months, insufficient and stress for 4 to 6 months, and handover and preparation for 7 to 12 months. Major sub-themes at 1 to 3 months were: rounds, intravenous-cannulation, medical device, and patient understanding; at 4 to 6 months they were admission, discharge, oxygen therapy, and disease; and at 7 to 12 months they were burden, independence, and solution. Conclusion: These results provide valuable insights into the challenges and experiences encountered by new nurses during different stages of their field adaptation process. This information may highlight the best nurse leadership methods for improving institutional education and supporting new nurses' transitions to the hospital work environment. | W8: [Ahn, Shin Hye; Jeong, Hye Won; Yang, Seong Gyeong; Jung, Ue Seok; Choi, Myoung Lee; Kim, Heui Seon] Chonnam Natl Univ Hosp, Dept Nursing, Gwangju, South Korea; [Jeong, Hye Won] Chonnam Natl Univ, Coll Nursing, Gwangju, South Korea; [Jeong, Hye Won] Korea Natl Univ Transportat, Dept Nursing, 61 Daehak ro,Yonggang ri,Jeungpyeong eup, Jeungpyeong 27909, South Korea | Y8: Jeong, HW (corresponding author), Korea Natl Univ Transportat, Dept Nursing, 61 Daehak ro,Yonggang ri,Jeungpyeong eup, Jeungpyeong 27909, South Korea. | Z8: hyewon1129@ut.ac.kr | AG8: 41 | AH8: 4 | AI8: 5 | AT8: JUN | AU8: 2024 | AV8: 54 | AW8: 3 | BB8: 358 | BC8: 371 | BE8: 10.4040/jkan.24034 | BF8: =HYPERLINK("http://dx.doi.org/10.4040/jkan.24034","http://dx.doi.org/10.4040/jkan.24034") -> http://dx.doi.org/10.4040/jkan.24034 | BR8: 2026-05-29 | BS8: WOS:001314085800007 | BT8: =HYPERLINK("https%3A%2F%2Fwww.webofscience.com%2Fwos%2Fwoscc%2Ffull-record%2FWOS:001314085800007","View Full Record in Web of Science") -> View Full Record in Web of Science | BU8: =COUNTIF('오픈소스&직접수집'!F:F,'wos(corecollection)_260528'!BE8) -> 1 | BV8: =COUNTIF('오픈소스&직접수집'!A:A,'wos(corecollection)_260528'!I8) -> 1 | BW8: =SUM(BU8:BV8) -> 2
A9: netminer 검색 | B9: Park, J; Park, S; Kim, MS | F9: Park, Jinah; Park, Shinaeh; Kim, Mi So | I9: Analyzivng Demand for Customized Obesity Prevention and Management Across Adult Age Groups Using Focus Group Interview | J9: INQUIRY-THE JOURNAL OF HEALTH CARE ORGANIZATION PROVISION AND FINANCING | N9: Article | V9: With the increasing obesity rates, many studies on obesity prevention and management have been implemented. However, few studies focused on obesity in adulthood and different perceptions of obesity between life cycles. Thus, this study aimed to investigate the demand for customized obesity prevention and management (OPM) strategies across adult age groups. Focus group interviews were conducted to gather insights from three age groups: young adults (20-34 years), middle-aged adults (35-49 years), and seniors (50-64 years). A total of 17 participants took part in the study, with 5 participants in Group 1, 6 participants in Group 2, and 6 participants in Group 3. Thematic analysis and the use of NetMiner version 4.4.3 facilitated data categorization and scrutiny. The study employed qualitative methods to explore perceptions of obesity and preferences for personalized OPM strategies among participants. Diverse perspectives on obesity as a health threat were found among the age groups. While all stressed the importance of personalized OPM, preferences for strategies varied. Diet and exercise combination emerged as a common preference. This study highlighted the need for customized OPM approaches aligned with age-specific preferences. | W9: [Park, Jinah] Seoul Natl Univ, Seoul, South Korea; [Park, Shinaeh] Korea Univ, Seoul, South Korea; [Kim, Mi So] Shinhan Univ, Dongducheon Si, Gyeonggi Do, South Korea | Y9: Kim, MS (corresponding author), Shinhan Univ, Coll Nursing, 30 Beolmadeul Ro 40Beon Gil, Dongducheon Si 11644, Gyeonggi Do, South Korea. | Z9: misoangel83@gmail.com | AG9: 46 | AH9: 3 | AI9: 4 | AU9: 2024 | AV9: 61 | BD9: 469580241271152 | BE9: 10.1177/00469580241271152 | BF9: =HYPERLINK("http://dx.doi.org/10.1177/00469580241271152","http://dx.doi.org/10.1177/00469580241271152") -> http://dx.doi.org/10.1177/00469580241271152 | BR9: 2026-05-29 | BS9: WOS:001298233300001 | BT9: =HYPERLINK("https%3A%2F%2Fwww.webofscience.com%2Fwos%2Fwoscc%2Ffull-record%2FWOS:001298233300001","View Full Record in Web of Science") -> View Full Record in Web of Science | BU9: =COUNTIF('오픈소스&직접수집'!F:F,'wos(corecollection)_260528'!BE9) -> 1 | BV9: =COUNTIF('오픈소스&직접수집'!A:A,'wos(corecollection)_260528'!I9) -> 1 | BW9: =SUM(BU9:BV9) -> 2
A10: netminer 검색 | B10: Lee, JJ; Kim, J; Lee, SK | F10: Lee, Jae-Joon; Kim, Jongwoo; Lee, Soo-Kyoung | I10: Trends of fear and anger on YouTube during the initial stage of the COVID-19 outbreak in South Korea | J10: BMC PUBLIC HEALTH | N10: Article | V10: Background The COVID-19 pandemic has been the most widespread and threatening health crisis experienced by the Korean society. Faced with an unprecedented threat to survival, society has been gripped by social fear and anger, questioning the culpability of this pandemic. This study explored the correlation between social cognitions and negative emotions and their changes in response to the severe events stemming from the COVID-19 pandemic in South Korea. Methods The analysis was based on a cognitive-emotional model that links fear and anger to the social causes that trigger them and used discursive content from comments posted on YouTube's COVID-19-related videos. A total of 182,915 comments from 1,200 videos were collected between January and December 2020. We performed data analyses and visualizations using R, Netminer 4.0, and Gephi software and calculated Pearson's correlation coefficients between emotions. Results YouTube videos were analyzed for keywords indicating cognitive assessments of major events related to COVID-19 and keywords indicating negative emotions. Eight topics were identified through topic modeling: causes and risks, perceptions of China, media and information, infection prevention rules, economic activity, school and infection, political leaders, and religion, politics, and infection. The correlation coefficient between fear and anger was 0.462 (p<.001), indicating a moderate linear relationship between the two emotions. Fear was the highest from January to March in the first year of the COVID-19 outbreak, while anger occurred before and after the outbreak, with fluctuations in both emotions during this period. Conclusions This study confirmed that social cognitions and negative emotions are intertwined in response to major events related to the COVID-19 pandemic, with each emotion varying individually rather than being ambiguously mixed. These findings could aid in developing social cognition-emotion-based public health strategies through education and communication during future pandemic outbreaks. | W10: [Lee, Jae-Joon] Sookmyung Womens Univ, Sookmyung Res Inst Humanities, 100 Cheongparo 47 Gel, Seoul 04310, South Korea; [Kim, Jongwoo] Yonsei Univ, Dept Sociol, BK21Four Program, 3-101,84 Mapo-Daero 11 Gil, Seoul 04133, South Korea; [Lee, Soo-Kyoung] Seoul Natl Univ, Bigdata Convergence & Open Sharing Syst 1, Seoul 08826, South Korea | Y10: Lee, SK (corresponding author), Seoul Natl Univ, Bigdata Convergence & Open Sharing Syst 1, Seoul 08826, South Korea. | Z10: soo1005@snu.ac.kr | AG10: 54 | AH10: 3 | AI10: 3 | AT10: JUN 4 | AU10: 2024 | AV10: 24 | AW10: 1 | BD10: 1496 | BE10: 10.1186/s12889-024-19023-6 | BF10: =HYPERLINK("http://dx.doi.org/10.1186/s12889-024-19023-6","http://dx.doi.org/10.1186/s12889-024-19023-6") -> http://dx.doi.org/10.1186/s12889-024-19023-6 | BR10: 2026-05-29 | BS10: WOS:001320257300007 | BT10: =HYPERLINK("https%3A%2F%2Fwww.webofscience.com%2Fwos%2Fwoscc%2Ffull-record%2FWOS:001320257300007","View Full Record in Web of Science") -> View Full Record in Web of Science | BU10: =COUNTIF('오픈소스&직접수집'!F:F,'wos(corecollection)_260528'!BE10) -> 1 | BV10: =COUNTIF('오픈소스&직접수집'!A:A,'wos(corecollection)_260528'!I10) -> 1 | BW10: =SUM(BU10:BV10) -> 2
A11: netminer 검색 | B11: Shin, SH; Baek, OJ | F11: Shin, Sun-Hwa; Baek, On-Jeon | I11: A Study on Internet News for Patient Safety Campaigns: Focusing on Text Network Analysis and Topic Modeling | J11: HEALTHCARE | N11: Article | V11: Background/Objectives: This study aimed to identify the main issues related to public patient safety campaigns reflected in Korean online news. This study utilized a text-mining method to identify keywords and topics related to patient safety campaigns. Methods: The data collection period was from 1 January 2022 to 31 December 2023, and 4110 news articles were extracted. Through data preprocessing, 2661 duplicated news and 1213 unrelated news were removed, and 236 news were selected. Using the NetMiner program, keyword co-occurrence frequency calculation, keyword centrality analysis, and topic modeling analysis were performed. Results: The results showed that the most frequently mentioned keywords with high degree centrality, betweenness centrality, and closeness centrality in online news were hospital, medical, medicine, project, and treatment. The topics of online news related to the patient safety campaign were patient-centered care for medical safety, health promotion projects at a regional institution, hand hygiene education to prevent infection, healthcare quality improvement through the Mint Festival, and safe use of medicines. Conclusions: This study analyzed patient safety campaign news topics using text network analysis and topic modeling. It was confirmed that patient safety campaigns are essential for fostering a patient safety culture, improving medical quality, and encouraging patient participation in hospitals. Therefore, to build a safe medical environment, it is necessary to establish an effective patient safety campaign for not only medical staff providing medical care, but also patients and their caregivers, and for this, cooperation and participation from various professional occupations are necessary. | W11: [Shin, Sun-Hwa; Baek, On-Jeon] Sahmyook Univ, Coll Nursing, Nursing Dept, Seoul 01795, South Korea | Y11: Baek, OJ (corresponding author), Sahmyook Univ, Coll Nursing, Nursing Dept, Seoul 01795, South Korea. | Z11: shinsh@syu.ac.kr; perfectoj@naver.com | AG11: 56 | AH11: 2 | AI11: 2 | AT11: OCT | AU11: 2024 | AV11: 12 | AW11: 19 | BD11: 1914 | BE11: 10.3390/healthcare12191914 | BF11: =HYPERLINK("http://dx.doi.org/10.3390/healthcare12191914","http://dx.doi.org/10.3390/healthcare12191914") -> http://dx.doi.org/10.3390/healthcare12191914 | BR11: 2026-05-29 | BS11: WOS:001331936100001 | BT11: =HYPERLINK("https%3A%2F%2Fwww.webofscience.com%2Fwos%2Fwoscc%2Ffull-record%2FWOS:001331936100001","View Full Record in Web of Science") -> View Full Record in Web of Science | BU11: =COUNTIF('오픈소스&직접수집'!F:F,'wos(corecollection)_260528'!BE11) -> 0 | BV11: =COUNTIF('오픈소스&직접수집'!A:A,'wos(corecollection)_260528'!I11) -> 1 | BW11: =SUM(BU11:BV11) -> 1
A12: netminer 검색 | B12: Kim, J | F12: Kim, Jongwon | I12: Analysis of football research trends using text network analysis | J12: PLOS ONE | N12: Article | V12: This study was aimed to identify football research trends in various periods. A total of 30,946 football papers were collected from a representative academic database and search engine, the 'Web of Science'. Keyword refinement included filtering nouns, establishing synonyms and thesaurus, and excluding conjunctions, and the Cyram's Netminer 4.0 software was used for network analysis. A centrality analysis was conducted by extracting the words corresponding to the top 2% of the main research topics to obtain the degree and eigenvector centralities. The most frequently mentioned research keywords were injury, performance, and club. Keyword performance showed the highest degree centrality (0.294) and keyword world and cup showed the highest eigenvector centrality (0.710). The keyword with the highest eigenvector degree changed from injury in the 1990s and world in the 2000s to cup since the 2010s. Although various studies on football injuries have been conducted, research on the sport itself has recently been conducted. This study provides fundamental information on football trends from research published over the past 30 years. | W12: [Kim, Jongwon] Middlesex Univ, London Sport Inst, Sch Sci & Technol, London, England | Y12: Kim, J (corresponding author), Middlesex Univ, London Sport Inst, Sch Sci & Technol, London, England. | Z12: jongwonkim1229@gmail.com | AG12: 46 | AH12: 1 | AI12: 1 | AT12: APR 18 | AU12: 2024 | AV12: 19 | AW12: 4 | BD12: e0299782 | BE12: 10.1371/journal.pone.0299782 | BF12: =HYPERLINK("http://dx.doi.org/10.1371/journal.pone.0299782","http://dx.doi.org/10.1371/journal.pone.0299782") -> http://dx.doi.org/10.1371/journal.pone.0299782 | BR12: 2026-05-29 | BS12: WOS:001207320100096 | BT12: =HYPERLINK("https%3A%2F%2Fwww.webofscience.com%2Fwos%2Fwoscc%2Ffull-record%2FWOS:001207320100096","View Full Record in Web of Science") -> View Full Record in Web of Science | BU12: =COUNTIF('오픈소스&직접수집'!F:F,'wos(corecollection)_260528'!BE12) -> 1 | BV12: =COUNTIF('오픈소스&직접수집'!A:A,'wos(corecollection)_260528'!I12) -> 1 | BW12: =SUM(BU12:BV12) -> 2
A13: netminer 검색 | B13: Yuan, JF; Chen, KW; Li, W; Ji, C; Wang, ZR; Skibniewski, MJ | F13: Yuan, Jingfeng; Chen, Kaiwen; Li, Wei; Ji, Chuang; Wang, Zhiru; Skibniewski, Miroslaw J. | I13: Social network analysis for social risks of construction projects in high-density urban areas in China | J13: JOURNAL OF CLEANER PRODUCTION | N13: Article | V13: Social impacts have become increasingly important for urban development in China. In addition, unlike general construction projects, construction projects in high-density urban areas have high levels of complexity and uncertainty. Thus, from a network perspective, an improved social risk analysis theory and a method for these projects were generated in this paper. A case study involving 66 cases of social conflicts in construction projects in China was performed, and 16 social risk factors were summarized. Eight stakeholders related to these social risk factors were then identified based on a literature review and the case database. A theoretical model for social risk network analysis considering the interrelationships between stakeholders and risks was developed by using NetMiner, a social network analysis (SNA) tool. A 2-mode network and two 1-mode networks were used to analyze the relationships among the identified 16 social risk factors and 8 stakeholders. In terms of three-level challenges such as complex environments, the unreasonable behavior of individuals or organizations, and diversified interaction between behaviors and environments, the most important social risks of construction projects in high-density urban areas were explored to help the government implement effective social risk management measures. In addition, multiple, complicated relationships among residents, contractors, governmental authorities, and owners represented a major factor leading to social risk; therefore, more attention should be focused on this topic. The proposed social risk analysis method can increase the attention paid by project managers, governmental authorities, and project owners to social risk factors in high-density areas and provide a structured framework to analyze such social risks, as well as put forth possible solutions to reduce the social impacts on construction projects in high-density urban areas. (C) 2018 Elsevier Ltd. All rights reserved. | W13: [Yuan, Jingfeng] Southeast Univ, Dept Construct & Real Estate, Nanjing 210096, Jiangsu, Peoples R China; [Chen, Kaiwen] Virginia Polytech Inst & State Univ, Dept Bldg Construct, Blacksburg, VA 24061 USA; [Li, Wei] Southeast Univ, Sch Civil Engn, Dept Construct & Real Estate, Nanjing 210096, Jiangsu, Peoples R China; [Ji, Chuang] Longyuan Future City Investment & Management Co L, Investment Dev Dept, Shanghai 200072, Peoples R China; [Wang, Zhiru] Univ Sci & Technol Beijing, Coll Econ & Management, Beijing 100083, Peoples R China; [Skibniewski, Miroslaw J.] Univ Maryland, Dept Civil & Environm Engn, College Pk, MD 20742 USA; [Skibniewski, Miroslaw J.] Polish Acad Sci, Inst Theoret & Appl Informat, Gliwice, Poland; [Skibniewski, Miroslaw J.] Chaoyang Univ Technol, Taichung, Taiwan | Y13: Yuan, JF (corresponding author), Southeast Univ, Dept Construct & Real Estate, Nanjing 210096, Jiangsu, Peoples R China. | Z13: jingfeng-yuan@seu.edu.cn; kwchen16@vt.edu; leewei0842@163.com; ji.chuang@hotmail.com; wangzhiru@ustb.edu.cn; mirek@umd.edu | AG13: 78 | AH13: 125 | AI13: 141 | AT13: OCT 10 | AU13: 2018 | AV13: 198 | BB13: 940 | BC13: 961 | BE13: 10.1016/j.jclepro.2018.07.109 | BF13: =HYPERLINK("http://dx.doi.org/10.1016/j.jclepro.2018.07.109","http://dx.doi.org/10.1016/j.jclepro.2018.07.109") -> http://dx.doi.org/10.1016/j.jclepro.2018.07.109 | BR13: 2026-05-29 | BS13: WOS:000442973100082 | BT13: =HYPERLINK("https%3A%2F%2Fwww.webofscience.com%2Fwos%2Fwoscc%2Ffull-record%2FWOS:000442973100082","View Full Record in Web of Science") -> View Full Record in Web of Science | BU13: =COUNTIF('오픈소스&직접수집'!F:F,'wos(corecollection)_260528'!BE13) -> 0 | BV13: =COUNTIF('오픈소스&직접수집'!A:A,'wos(corecollection)_260528'!I13) -> 0 | BW13: =SUM(BU13:BV13) -> 0
A14: netminer 검색 | B14: Morashti, JA; An, Y; Jang, H | F14: Morashti, Jonathan Asher; An, Youra; Jang, Hyunmi | I14: A Systematic Literature Review of Sustainable Packaging in Supply Chain Management | J14: SUSTAINABILITY | N14: Article | V14: This exploratory study utilises quantitative analysis to deliver a systematic literature review of published journal papers from 1993 to 2020 with the aim to identify research trends and present a comprehensive overview of research focus conducted in the sustainable packaging domain within the scope of supply chain management. This research is conducted with the data mining software, NetMiner 4, utilising the three analytical tools of statistical analysis, keyword network analysis, and topic analysis. The research also utilises the qualitative method of in-depth interviews in order to investigate current trends and perspectives on the future of sustainable packaging and to validate the analysis results. The research findings reveal that research in the field of 'sustainable packaging in supply chain management' field has been extremely limited, and this study acts to address this research gap. The results confirm that the vast majority of research focus has been in the fields of engineering and science. Research on the topic has gained momentum and has significantly increased since 2013 with research trends becoming increasingly diversified and gradually aligned with the concept of circular economy, while the topic of operational management has been highlighted as an area requiring additional attention. The keyword frequency analysis reveals the following highest occurring keywords in TF: life cycle; environmental impact; consumer; transportation; and production. The highest occurring keywords in TF-IDF: production; transportation; consumer; food; and environmental impact. Topic modelling revealed the following six topics: consumer behaviour; environmental pollution; circular economy; waste management; resource conservation; and operational management. This study contributes to understanding past, present, and future research agendas, and can be utilised as foundation for research development, as it provides insight to current research status and trends provided by the keyword network analysis highlighting research focus and trends in 'sustainable packaging in supply chain management'. | W14: [Morashti, Jonathan Asher; An, Youra; Jang, Hyunmi] Pusan Natl Univ, Grad Sch Int Studies, Busan 46241, South Korea | Y14: Jang, H (corresponding author), Pusan Natl Univ, Grad Sch Int Studies, Busan 46241, South Korea. | Z14: jamorashti@pusan.ac.kr; youraan@pusan.ac.kr; jangh01@pusan.ac.kr | AG14: 61 | AH14: 36 | AI14: 41 | AT14: MAY | AU14: 2022 | AV14: 14 | AW14: 9 | BD14: 4921 | BE14: 10.3390/su14094921 | BF14: =HYPERLINK("http://dx.doi.org/10.3390/su14094921","http://dx.doi.org/10.3390/su14094921") -> http://dx.doi.org/10.3390/su14094921 | BR14: 2026-05-29 | BS14: WOS:000794598300001 | BT14: =HYPERLINK("https%3A%2F%2Fwww.webofscience.com%2Fwos%2Fwoscc%2Ffull-record%2FWOS:000794598300001","View Full Record in Web of Science") -> View Full Record in Web of Science | BU14: =COUNTIF('오픈소스&직접수집'!F:F,'wos(corecollection)_260528'!BE14) -> 1 | BV14: =COUNTIF('오픈소스&직접수집'!A:A,'wos(corecollection)_260528'!I14) -> 1 | BW14: =SUM(BU14:BV14) -> 2
A15: netminer 검색 | B15: Kim, D; Kim, S | F15: Kim, Dongwook; Kim, Sungbum | I15: The Role of Mobile Technology in Tourism: Patents, Articles, News, and Mobile Tour App Reviews | J15: SUSTAINABILITY | N15: Review | V15: The purpose of this research is to identify the status and role of mobile technology in achieving sustainable and smart tourism, and to suggest future research and strategy directions for academia and managers in practice. This research utilized multiple sources, such as patents, academic articles, and news, and selected methodologies optimized for the purpose of each study. Study 1 used Netminer, a social network analysis program, to analyze the relationships between patent's International Patent Classification (IPC) codes. Study 2 used the T-LAB program for content analysis to analyze the texts of patents, journal articles, and news. Study 3 used the Leximancer program, which utilizes relative frequency to analyze mobile app consumer reviews. In study 1, we identified various forms of data related technologies and mobile technologies for smart city systems and maps. In study 2, we found the environment, sustainability, business, and market themes to be related to mobile technology. In study 3, we explored consumers' attitudes and preferences for mobile travel app using their reviews. Advances in mobile technology are expected to create innovative experiences for consumers, foster a sustainable competitive advantage for tourism destinations and tourism-related suppliers, and create sustainable competencies for smart tourism. | W15: [Kim, Dongwook] Korea Adv Inst Sci & Technol, Grad Sch Innovat & Technol Management, Daejeon 305701, South Korea; [Kim, Sungbum] Kumoh Natl Inst Technol, Dept IT Convergence, Gumi 730701, Gyungbuk, South Korea | Y15: Kim, S (corresponding author), Kumoh Natl Inst Technol, Dept IT Convergence, Gumi 730701, Gyungbuk, South Korea. | Z15: heavenk1@kaist.ac.kr; it89@kumoh.ac.kr | AG15: 200 | AH15: 83 | AI15: 103 | AT15: NOV | AU15: 2017 | AV15: 9 | AW15: 11 | BD15: 2082 | BE15: 10.3390/su9112082 | BF15: =HYPERLINK("http://dx.doi.org/10.3390/su9112082","http://dx.doi.org/10.3390/su9112082") -> http://dx.doi.org/10.3390/su9112082 | BR15: 2026-05-29 | BS15: WOS:000416793400161 | BT15: =HYPERLINK("https%3A%2F%2Fwww.webofscience.com%2Fwos%2Fwoscc%2Ffull-record%2FWOS:000416793400161","View Full Record in Web of Science") -> View Full Record in Web of Science | BU15: =COUNTIF('오픈소스&직접수집'!F:F,'wos(corecollection)_260528'!BE15) -> 0 | BV15: =COUNTIF('오픈소스&직접수집'!A:A,'wos(corecollection)_260528'!I15) -> 0 | BW15: =SUM(BU15:BV15) -> 0
A16: netminer 검색 | B16: Seon, SH; Jeong, HW; Ju, D; Lee, JA; Ahn, SH | F16: Seon, Sun Hee; Jeong, Hye Won; Ju, Deok; Lee, Jung A. A.; Ahn, Shin Hye | I16: Capturing New Nurses' Experiences and Supporting Critical Thinking Text Network Analysis of Critical Reflective Journals | J16: CIN-COMPUTERS INFORMATICS NURSING | N16: Article | V16: This study analyzed the contents of critical reflective journals written by new nurses during their orientations using a text network. This study aimed to find ways to reduce turnover and improve clinical field adaptability among new nurses. The authors analyzed the content of reflective journals written by 143 new nurses from March 2020 to January 2021. Text network analysis was performed using the NetMiner 4.4.3 program. After data preprocessing, frequency of occurrence, degree centrality, closeness centrality, betweenness centrality, and eigenvector community were analyzed. In total, 453 words were extracted and refined, and words with high simple frequency and centrality were incompetence, preparation, explanation, injection, time, examination, and first try. Medication had the highest frequency of occurrence, and incompetence was the most important keyword in the centrality analysis. In addition, component analysis and eigenvector community analysis revealed three sub-theme groups: (1) basic nursing skills required for new nurses, (2) insufficient competency, and (3) explanation of nursing work. Significantly, this study is the first to use the text network method to analyze the subjective experiences of the critical reflective journals of new nurses. In conclusion, changes are needed to improve the education system for new nurses and promote efficient sharing of nursing tasks. | W16: [Seon, Sun Hee; Ju, Deok; Lee, Jung A. A.; Ahn, Shin Hye] Chonnam Natl Univ Hosp, Gwangju, South Korea; [Jeong, Hye Won] Chonnam Natl Univ, Chonnam Natl Univ Hosp, Gwangju, South Korea; [Jeong, Hye Won] Chonnam Nat Univ Hosp, Dept Nursing, 42 Jebong Ro, Gwangju 61469, South Korea; [Jeong, Hye Won] Chonnam Natl Univ, Coll Nursing, 160 Baekseo Ro, Gwangju 61469, South Korea | Y16: Jeong, HW (corresponding author), Chonnam Nat Univ Hosp, Dept Nursing, 42 Jebong Ro, Gwangju 61469, South Korea.;Jeong, HW (corresponding author), Chonnam Natl Univ, Coll Nursing, 160 Baekseo Ro, Gwangju 61469, South Korea. | Z16: seon00509@hanmail.net; y2k331646@gmail.com; juyulianna@hanmail.net; cuttylja@hanmail.net; chunyanggirl@naver.com | AG16: 40 | AH16: 6 | AI16: 7 | AT16: JUN | AU16: 2023 | AV16: 41 | AW16: 6 | BB16: 434 | BC16: 441 | BE16: 10.1097/CIN.0000000000000971 | BF16: =HYPERLINK("http://dx.doi.org/10.1097/CIN.0000000000000971","http://dx.doi.org/10.1097/CIN.0000000000000971") -> http://dx.doi.org/10.1097/CIN.0000000000000971 | BR16: 2026-05-29 | BS16: WOS:001000492200010 | BT16: =HYPERLINK("https%3A%2F%2Fwww.webofscience.com%2Fwos%2Fwoscc%2Ffull-record%2FWOS:001000492200010","View Full Record in Web of Science") -> View Full Record in Web of Science | BU16: =COUNTIF('오픈소스&직접수집'!F:F,'wos(corecollection)_260528'!BE16) -> 1 | BV16: =COUNTIF('오픈소스&직접수집'!A:A,'wos(corecollection)_260528'!I16) -> 1 | BW16: =SUM(BU16:BV16) -> 2
A17: netminer 검색 | B17: Kim, MS | F17: Kim, Mee Sook | I17: Topics model of overwork-related deaths in Korea and the implications of SDGs' decent work perspective | J17: SAFETY SCIENCE | N17: Article | V17: Objective: Through a text network analysis, this study examined major issues related to death from overwork reported in Korean media over the past ten years, focusing on essential workers, and examined the implications for Korean society from the perspective of decent work as described by the Sustainable Development Goals (SDGs). Methods: We retrieved 1,340 news articles from 52 media companies by searching for death from overwork as a keyword using the Big Kinds database operated by the Korea Press Foundation. A total of 4,627 nouns were extracted from news articles, and four topics were found by performing topic modeling using the NetMiner 4 program. We also examined the trend of topic ratios by year. Results: Between 2012 and 2015, 22-36 news articles were reported annually, and Topic 2 (recognition of death from overwork of public officials) was the most common. Between 2016 and 2019, 72-162 news articles were reported annually, and Topic 1 (postal workers' extended working hours) was the most common. Between 2020 and 2021, 314-441 news articles were reported annually, and Topic 3 (measures against industrial accidents of courier workers) and Topic 4 (courier sorting and labor union consensus) were the most common. Conclusion: In Korea, postal workers, public officials, and courier workers are vulnerable to death from overwork. This can be resolved by considerably reducing working hours, recognizing industrial accidents, and improving the working environment. From the perspective of the United Nations Development Programme (UNDP) SDGs' decent work concept, to sustain workers' health and well-being, the State and companies should guarantee workers healthy working hours, choice of working hours, guarantee of decent and productive work, and maximum working hours cap system. The labor system and workplace culture should be improved to guarantee workers' health and well-being. | W17: [Kim, Mee Sook] Catholic Kkottongnae Univ, Dept Liberal Arts, 33 Sangsam gil, Cheongju Shi 28211, South Korea | Y17: Kim, MS (corresponding author), Catholic Kkottongnae Univ, Dept Liberal Arts, 33 Sangsam gil, Cheongju Shi 28211, South Korea. | Z17: mskjeon@kkot.ac.kr | AG17: 39 | AH17: 6 | AI17: 7 | AT17: OCT | AU17: 2023 | AV17: 166 | BD17: 106239 | BE17: 10.1016/j.ssci.2023.106239 | BF17: =HYPERLINK("http://dx.doi.org/10.1016/j.ssci.2023.106239","http://dx.doi.org/10.1016/j.ssci.2023.106239") -> http://dx.doi.org/10.1016/j.ssci.2023.106239 | BH17: JUN 2023 | BR17: 2026-05-29 | BS17: WOS:001030993100001 | BT17: =HYPERLINK("https%3A%2F%2Fwww.webofscience.com%2Fwos%2Fwoscc%2Ffull-record%2FWOS:001030993100001","View Full Record in Web of Science") -> View Full Record in Web of Science | BU17: =COUNTIF('오픈소스&직접수집'!F:F,'wos(corecollection)_260528'!BE17) -> 0 | BV17: =COUNTIF('오픈소스&직접수집'!A:A,'wos(corecollection)_260528'!I17) -> 1 | BW17: =SUM(BU17:BV17) -> 1
